<sdf version='1.9'>
  <world name='tracer'>
    <physics name="1ms" type="ignored">
      <max_step_size>0.001</max_step_size>
      <real_time_factor>1.0</real_time_factor>
    </physics>

    <plugin filename="gz-sim-physics-system" name="gz::sim::systems::Physics"/>
    <plugin filename="gz-sim-user-commands-system" name="gz::sim::systems::UserCommands"/>
    <plugin filename="gz-sim-scene-broadcaster-system" name="gz::sim::systems::SceneBroadcaster"/>
    <plugin
      filename="ignition-gazebo-sensors-system"
      name="ignition::gazebo::systems::Sensors">
      <render_engine>ogre2</render_engine>
    </plugin>
    <gravity>0 0 -9.8</gravity>

    <light type="directional" name="sun">
      <cast_shadows>true</cast_shadows>
      <pose>0 0 10 0 0 0</pose>
      <diffuse>0.8 0.8 0.8 1</diffuse>
      <specular>0.2 0.2 0.2 1</specular>
      <attenuation>
        <range>1000</range>
        <constant>0.9</constant>
        <linear>0.01</linear>
        <quadratic>0.001</quadratic>
      </attenuation>
      <direction>-0.5 0.1 -0.9</direction>
    </light>

    <model name="ground_plane">
      <static>true</static>
      <link name="link">
        <collision name="collision">
          <geometry>
            <plane>
              <normal>0 0 1</normal>
              <size>100 100</size>
            </plane>
          </geometry>
        </collision>
        <visual name="visual">
          <geometry>
            <plane>
              <normal>0 0 1</normal>
              <size>100 100</size>
            </plane>
          </geometry>
          <material>
            <ambient>0.8 0.8 0.8 1</ambient>
            <diffuse>0.8 0.8 0.8 1</diffuse>
            <specular>0.8 0.8 0.8 1</specular>
          </material>
        </visual>
      </link>
    </model>


    <model name="unpredictable_car">
      <pose>2 0 0.5 0 0 0</pose>
      <self_collide>false</self_collide>
      <static>false</static>

      <link name="chassis">
        <pose>0 0 0.1 0 0 0</pose>
        <inertial>
          <mass>1.0</mass>
          <inertia>
            <ixx>0.001</ixx><iyy>0.001</iyy><izz>0.001</izz>
          </inertia>
        </inertial>
        <visual name="visual">
          <geometry><box><size>0.4 0.2 0.1</size></box></geometry>
          <material>
            <ambient>1 0 0 1</ambient>   
            <diffuse>1 0 0 1</diffuse>   
            <specular>0.5 0.5 0.5 1</specular> 
          </material>
        </visual>
        <collision name="collision">
          <geometry><box><size>0.4 0.2 0.1</size></box></geometry>
        </collision>
      </link>

      <link name="left_wheel">
        <pose>0 0.15 0.1 -1.5707 0 0</pose>
        <inertial>
          <mass>0.1</mass>
          <inertia>
            <ixx>0.0001</ixx><iyy>0.0001</iyy><izz>0.0001</izz>
          </inertia>
        </inertial>
        <visual name="visual">
          <geometry><cylinder><radius>0.1</radius><length>0.05</length></cylinder></geometry>
          <material>
            <ambient>1 0 0 1</ambient>   
            <diffuse>1 0 0 1</diffuse>   
            <specular>0.5 0.5 0.5 1</specular> 
          </material>
        </visual>
        <collision name="collision">
          <geometry><cylinder><radius>0.1</radius><length>0.05</length></cylinder></geometry>

        </collision>
      </link>

      <link name="right_wheel">
        <pose>0 -0.15 0.1 -1.5707 0 0</pose>
        <inertial>
          <mass>0.1</mass>
          <inertia>
            <ixx>0.0001</ixx><iyy>0.0001</iyy><izz>0.0001</izz>
          </inertia>
        </inertial>
        <visual name="visual">
          <geometry><cylinder><radius>0.1</radius><length>0.05</length></cylinder></geometry>
          <material>
            <ambient>1 0 0 1</ambient>   
            <diffuse>1 0 0 1</diffuse>   
            <specular>0.5 0.5 0.5 1</specular> 
          </material>       
        </visual>
        <collision name="collision">
          <geometry><cylinder><radius>0.1</radius><length>0.05</length></cylinder></geometry>
        </collision>
      </link>

      <joint name="left_wheel_joint" type="revolute">
        <parent>chassis</parent>
        <child>left_wheel</child>
        <axis><xyz>0 0 1</xyz></axis>
      </joint>

      <joint name="right_wheel_joint" type="revolute">
        <parent>chassis</parent>
        <child>right_wheel</child>
        <axis><xyz>0 0 1</xyz></axis>
      </joint>

      <plugin
        filename="gz-sim-diff-drive-system"
        name="gz::sim::systems::DiffDrive">
        <left_joint>left_wheel_joint</left_joint>
        <right_joint>right_wheel_joint</right_joint>
        <wheel_separation>0.3</wheel_separation>
        <wheel_radius>0.1</wheel_radius>
        <topic>/cmd_vel</topic> 
      </plugin>
    </model>

  </world>
</sdf>